<?xml version="1.0" ?>
<robot name="rover_se_pernas" xmlns:xacro="http://www.ros.org/wiki/xacro">

<xacro:include filename="$(find rover_se_pernas_description)/urdf/materials.xacro" />
<xacro:include filename="$(find rover_se_pernas_description)/urdf/rover_se_pernas.ros2control" />
<xacro:include filename="$(find rover_se_pernas_description)/urdf/rover_se_pernas.gazebo" />
<link name="base_link">
  <inertial>
    <origin xyz="0.4882383881861825 0.14983639102105517 1.1930603195605387" rpy="0 0 0"/>
    <mass value="46.37689397650178"/>
    <inertia ixx="2.002069" iyy="3.88283" izz="4.845997" ixy="0.001994" iyz="-0.000599" ixz="0.602482"/>
  </inertial>
  <visual>
    <origin xyz="0 0 0" rpy="0 0 0"/>
    <geometry>
      <mesh filename="file://$(find rover_se_pernas_description)/meshes/base_link.stl" scale="0.001 0.001 0.001"/>
    </geometry>
    <material name="silver"/>
  </visual>
  <collision>
    <origin xyz="0 0 0" rpy="0 0 0"/>
    <geometry>
      <mesh filename="file://$(find rover_se_pernas_description)/meshes/base_link.stl" scale="0.001 0.001 0.001"/>
    </geometry>
  </collision>
</link>

<link name="body_four_2">
  <inertial>
    <origin xyz="-0.02755717247325251 -0.047631594014974965 0.005362083573672183" rpy="0 0 0"/>
    <mass value="8.776606415040463"/>
    <inertia ixx="0.070797" iyy="0.094821" izz="0.060955" ixy="0.018011" iyz="-0.000257" ixz="0.00048"/>
  </inertial>
  <visual>
    <origin xyz="-0.833215 -0.635473 -0.908273" rpy="0 0 0"/>
    <geometry>
      <mesh filename="file://$(find rover_se_pernas_description)/meshes/body_four_2.stl" scale="0.001 0.001 0.001"/>
    </geometry>
    <material name="silver"/>
  </visual>
  <collision>
    <origin xyz="-0.833215 -0.635473 -0.908273" rpy="0 0 0"/>
    <geometry>
      <mesh filename="file://$(find rover_se_pernas_description)/meshes/body_four_2.stl" scale="0.001 0.001 0.001"/>
    </geometry>
  </collision>
</link>

<link name="body_five_v7_1">
  <inertial>
    <origin xyz="0.0007132810319058214 0.00426127025979034 -0.024439211831007723" rpy="0 0 0"/>
    <mass value="11.344297853514144"/>
    <inertia ixx="0.034487" iyy="1.409892" izz="1.396504" ixy="0.000254" iyz="-0.003774" ixz="-0.000343"/>
  </inertial>
  <visual>
    <origin xyz="-0.360009 -0.49 -1.192273" rpy="0 0 0"/>
    <geometry>
      <mesh filename="file://$(find rover_se_pernas_description)/meshes/body_five_v7_1.stl" scale="0.001 0.001 0.001"/>
    </geometry>
    <material name="silver"/>
  </visual>
  <collision>
    <origin xyz="-0.360009 -0.49 -1.192273" rpy="0 0 0"/>
    <geometry>
      <mesh filename="file://$(find rover_se_pernas_description)/meshes/body_five_v7_1.stl" scale="0.001 0.001 0.001"/>
    </geometry>
  </collision>
</link>

<link name="body_three_1">
  <inertial>
    <origin xyz="0.0020044111265539177 0.0038744475994180183 -0.17574654012655755" rpy="0 0 0"/>
    <mass value="8.11027433263604"/>
    <inertia ixx="0.062849" iyy="0.054085" izz="0.027423" ixy="-0.006628" iyz="0.005342" ixz="0.002834"/>
  </inertial>
  <visual>
    <origin xyz="-0.770009 -0.51732 -1.133273" rpy="0 0 0"/>
    <geometry>
      <mesh filename="file://$(find rover_se_pernas_description)/meshes/body_three_1.stl" scale="0.001 0.001 0.001"/>
    </geometry>
    <material name="silver"/>
  </visual>
  <collision>
    <origin xyz="-0.770009 -0.51732 -1.133273" rpy="0 0 0"/>
    <geometry>
      <mesh filename="file://$(find rover_se_pernas_description)/meshes/body_three_1.stl" scale="0.001 0.001 0.001"/>
    </geometry>
  </collision>
</link>

<joint name="Revolucionar 16" type="continuous">
  <origin xyz="0.063206 0.118153 -0.225" rpy="0 0 0"/>
  <parent link="body_three_1"/>
  <child link="body_four_2"/>
  <axis xyz="0.471778 0.881717 -0.0"/>
</joint>

<joint name="Rígido 20" type="fixed">
  <origin xyz="0.360009 0.49 1.192273" rpy="0 0 0"/>
  <parent link="base_link"/>
  <child link="body_five_v7_1"/>
</joint>

<joint name="Revolucionar 21" type="continuous">
  <origin xyz="0.41 0.02732 -0.059" rpy="0 0 0"/>
  <parent link="body_five_v7_1"/>
  <child link="body_three_1"/>
  <axis xyz="0.0 0.0 -1.0"/>
</joint>

</robot>
